import datetime
from odoo import api, fields, models
from odoo.exceptions import ValidationError

class CancelAppointmentWizard(models.TransientModel):
    _name = "cancel.appointment.wizard"
    _description = "Cancel Appointment Wizard"

    @api.model
    def default_get(self, fields):
        res = super(CancelAppointmentWizard,self).default_get(fields)
        res['date_cancel'] = datetime.date.today()
        return res

    appointment_id = fields.Many2one('hospital.appointment', string="Appointment")
    reason = fields.Text(string="Reason")
    date_cancel = fields.Date(string="Cancellation Date")

    def action_cancel(self):
        if self.appointment_id.booking_date == fields.Date.today():
            raise ValidationError("Sorry,Cancellation is not allowed for the same day. ")
        return